Workbook

Sheet UAT · Start here
B1: OpenMaison 2.0 — User acceptance test
B2: Walk through 2.0 the way a studio would on its first day, and tell us what works, what doesn’t, and what you miss from 1.0.
B4: The story
B5: Demo Studio has just moved from OpenMaison 1.0 to 2.0. Its team, leads and quotes came across with it. You are Dane, the studio owner, logging in for the first time. Over thirteen chapters you set up the studio, receive leads, and take one new client — Sophia Wong, 9765 4321, a 4-room HDB in Tampines — from first call to signed contract. Then you look at the studio as a designer would, review the week, do it all again on your phone, and finally design Sophia’s living room in the AI Visualizer.
B7: Before you start
B8: 1. Open the prototype | C8: In Terminal, in the openmaison-prototype folder: git pull, then npm run dev. Open http://localhost:3000 in Chrome, window at full width.
B9: 2. Start clean | C9: Click the ✦ button (bottom right) › “Reset prototype to base”. Do this ONCE, before chapter 1. Resetting later wipes Sophia Wong and your progress.
B10: 3. Your tab | C10: Work only in your own tab (UAT · Dane, UAT · Oliva, UAT · Swati). Go in order — each chapter continues from the one before.
B11: 4. Time | C11: About 30–60 minutes a chapter. Stop at a chapter’s end; the prototype remembers where you are.
B13: How to answer
B14: ✅ Works | C14: It did what “You should see” says.
B15: 🟡 Works, but… | C15: It worked, but something felt wrong, slow, unclear or different from what you expected — say what in “What happened”.
B16: ❌ Doesn’t work | C16: It did not do what “You should see” says, or showed an error — say what you did and what you saw.
B17: 🔍 Couldn’t find it | C17: You could not find the button, page or option — say where you looked.
B18: ⏭️ Skipped | C18: You could not try it (for example, an earlier step failed) — say why.
B19: Screenshot | C19: Mac: Cmd + Shift + 4, drag over the screen, then drop the file into the team’s Drive folder and paste its link. Windows: Win + Shift + S.
B20: Re-tested | C20: When Status says “Fixed – please re-test”, try the step again and pick ✅ Fixed now or ❌ Still not right.
B22: Good to know
B23: View as | C23: Click “Demo Studio” at the bottom of the left menu to see the prototype as another member (a designer, the manager, the admin). Chapter 10 uses it. Switch back to Dane when a step says so — the bottom-left always shows who you are.
B24: WhatsApp | C24: Some steps open WhatsApp in a new tab. Close it — never press Send. The prototype does not message anyone.
B25: Client pages | C25: Where the client confirms a quote or signs a contract, you copy the link from the prototype and open it in a new tab — you play the client.
B26: Your phone | C26: Chapter 12: when npm run dev starts, Terminal shows a “Network” address (like http://192.168.1.5:3000). Open it on a phone on the same Wi-Fi.
B27: Sample files | C27: Steps that need a file name it — open http://localhost:3000/uat-files/ plus the file name to download it.
B28: Not in 2.0 on purpose | C28: Journey mode (2.0 moves leads stage by stage), Archive (2.0 uses Delete with a Deleted list), Meetings, Dashboard, Projects, Marketplace and Chat. Their buttons answer “Coming soon in OpenMaison 2.0” — that is expected, not a bug.
B29: Something else? | C29: Anything the story does not cover — especially something you did in 1.0 and cannot find here — goes in “UAT · Missing or other”.
B30: Questions | C30: Ask Vicky or Dane.
B32: Example of a filled row
B33: Step | C33: 4.03
B34: Try this | C34: Add a lead with a phone number that already exists
B35: Result | C35: 🟡 Works, but…
B36: What happened | C36: The warning came up, but I expected it to also show the lead’s stage.
B38: Sample files
B39: paynow-qr.png | C39: http://localhost:3000/uat-files/paynow-qr.png — Stands in for the PayNow QR a bank gives the studio (step 2.03). Any picture works — the prototype shows its own sample QR once one is picked.
B40: fluted-panel.jpg | C40: http://localhost:3000/uat-files/fluted-panel.jpg — The photo for the tester's own price-book item, Fluted feature wall panel (step 3.05).
B41: supplier-price-list.csv | C41: http://localhost:3000/uat-files/supplier-price-list.csv — A supplier's price list imported into My Items (steps 3.12–3.13): two new items, one match on an existing item (name + vendor), one repeated row, one new trade.
B42: new-leads.xlsx | C42: http://localhost:3000/uat-files/new-leads.xlsx — 4.06–4.08 and 4.11: the spreadsheet import — 3 clean leads (one from Qanvast), 1 repeat of the seeded Gerald Tan (same phone) to exercise Review › merge, 1 row with no name that the import skips.
B43: homematch-lead-sheet.pdf | C43: http://localhost:3000/uat-files/homematch-lead-sheet.pdf — 4.09: a portal's PDF lead sheet (two leads) read by the import's PDF reader (labelled 'Label: value' lines).
B44: sophia-floor-plan.pdf | C44: http://localhost:3000/uat-files/sophia-floor-plan.pdf — 4.05: attached to Sophia Wong's lead when she is created; 5.14 finds it in her Files tab.
B45: sophia-living-room.jpg | C45: http://localhost:3000/uat-files/sophia-living-room.jpg — 5.15: uploaded into the 'Site photos' folder on Sophia Wong's Files tab (5.16 comments on it; 13.01 opens it in the AI Visualizer).
B46: sophia-items-to-paste.xlsx | C46: http://localhost:3000/uat-files/sophia-items-to-paste.xlsx — Chapter 6 (6.07): a block of quote lines the tester copies in Excel / Numbers / Google Sheets and pastes into Sophia’s Items table. Chapter 7 (7.10) reuses it as “Your quote” in Upload two quotes.
...

Sheet UAT · Dane
A1: Dane — the whole story, chapter by chapter
A2: Go in order. Read “Try this”, follow “How”, compare with “You should see”, then pick a Result. Write in “What happened” only when it is not ✅. White columns are yours; grey columns are Vicky’s and Dane’s. See “UAT · Start here” first.
A3: Ch | B3: Step | C3: Scene | D3: Module | E3: Try this | F3: How | G3: You should see | H3: In 1.0 | I3: You are | J3: Result | K3: What happened (only if not ✅) | L3: Screenshot link | M3: Date tested | N3: Our reply | O3: Status | P3: Re-tested
A4: Chapter 1 · First login — Look around your new workspace.
A5: 1 | B5: 1.01 | C5: Start fresh and look around | D5: Shell | E5: Start from the studio's day-one data | F5: 1. Open http://localhost:3000 2. Click the ✦ "Maison AI" button, bottom right 3. Click "Reset prototype to base" 4. Click "Reset" | G5: A "Reset the prototype?" box warns that anything tried is lost; after "Reset" the Leads page reloads. | H5: New in 2.0 | I5: Dane
A6: 1 | B6: 1.02 | C6: Start fresh and look around | D6: Shell | E6: Find your way around the side navigation | F6: 1. Point at the logo, top left, and click "Expand navigation" 2. Read the items from top to bottom 3. Click "Collapse navigation" | G6: Search ("/"), Dashboard, Tasks, Projects, Leads, Marketplace, Company, Qanvast Ops; then Upgrade, Tools, Chat, Notifications, Settings; Demo Studio at the bottom. | H6: Different from 1.0: Settings in the side navigation, not the profile menu | I6: Dane
A7: 1 | B7: 1.03 | C7: Your leads at a glance | D7: Leads | E7: See the studio's leads at a glance | F7: 1. Click "Leads" in the side navigation 2. Look at the chip above the table, the rows and the bottom of the screen | G7: The chip reads "All Leads (27)"; unopened new leads (Marcus Chen, Nur Aisyah) have a coloured left edge; a "Review imported leads" bar waits below. | H7: Different from 1.0: unopened new leads are marked | I7: Dane
A8: 1 | B8: 1.04 | C8: Your leads at a glance | D8: Leads | E8: Find a lead fast with the / key | F8: 1. On Leads, press the / key 2. Type Kenji 3. Clear the search box | G8: The search box takes the cursor; only Kenji Sato stays in the list; clearing the box brings everyone back. | H8: Same as 1.0 | I8: Dane
A9: 1 | B9: 1.05 | C9: Your leads at a glance | D9: Leads | E9: Try editing the lead stages | F9: 1. Click the "All Leads (27)" chip 2. Read the stage list 3. Click "Manage Stages" | G9: Each stage is listed with its count under Active and Inactive; "Manage Stages" answers "Coming soon in OpenMaison 2.0". | H9: Different from 1.0: stages are fixed; 1.0 edited its funnel | I9: Dane
A10: 1 | B10: 1.06 | C10: Where everything else lives | D10: Shell | E10: See the tools the studio can use | F10: 1. Click "Tools" in the side navigation 2. Read the tiles 3. Click "AI Visualizer" | G10: Nine tiles, starting with Quotes, Quote X-Ray and Contracts; "AI Visualizer" opens the AI Visualizer — Kevin Ng's design and the "Showroom ideas" folder (REG-673). | H10: Same as 1.0 | I10: Dane
A11: 1 | B11: 1.07 | C11: Where everything else lives | D11: Company | E11: See where the studio's records are kept | F11: 1. Click "Company" in the side navigation 2. Read the two groups 3. Press Esc | G11: "Studio": Profile, Members, Questionnaire, Templates ("1 awaiting"), Price book ("1 proposed"). "Operations": Finance and Reports marked "Soon", Integrations. | H11: Different from 1.0: records under Company, rules under Settings | I11: Dane
A12: 1 | B12: 1.08 | C12: Where everything else lives | D12: Notifications | E12: Check what is waiting for you in the bell | F12: 1. Click "Notifications" (the bell) in the side navigation 2. Read the list 3. Close it without clicking a row | G12: A "Notifications" panel lists notices newest first, e.g. "New lead: Nur Aisyah"; unread ones have a dot; "Notification settings" sits at the foot. | H12: Different from 1.0: follow-ups due appear in the same list | I12: Dane
A13: 1 | B13: 1.09 | C13: Where everything else lives | D13: Shell | E13: Ask Maison AI for help on the Leads page | F13: 1. On Leads, click the ✦ "Maison AI" button 2. Read the suggestions 3. Click "Which leads need follow-up today?" | G13: Suggestions about your leads sit above "Reset prototype to base"; picking one answers "Coming soon in OpenMaison 2.0". | H13: Different from 1.0: scripted suggestions only, in the prototype | I13: Dane
A14: Chapter 2 · Set up your studio — Company details, your team and the studio’s rules.
A15: 2 | B15: 2.01 | C15: Your company on paper | D15: Company | E15: Open your company's profile | F15: 1. Click "Company" in the side navigation 2. Click "Profile" | G15: "Company details" shows Demo Studio Pte Ltd, its UEN and address; the right side shows "Default template · Default Quote PDF". | H15: Different from 1.0: company records live under Company, not Accounts | I15: Dane
A16: 2 | B16: 2.02 | C16: Your company on paper | D16: Company | E16: Add a tagline and your Instagram handle | F16: 1. In "Tagline" type Homes that feel like you 2. Under "Social links", in "Instagram" type @demostudio.sg 3. Click "Save changes" | G16: A message says "Company details saved"; "Save changes" and "Discard" grey out until you change something again. | H16: Same as 1.0 | I16: Dane
A17: 2 | B17: 2.03 | C17: Your company on paper | D17: Company | E17: Put the studio's bank account and PayNow on file | F17: 1. Scroll to "Issuing entities & bank details" 2. For Demo Studio Pte Ltd fill "Bank" DBS Bank, "Account number" 072-123456-7, "SWIFT / BIC" DBSSSGSG, "PayNow (UEN or mobile)" 201234567M 3. Click the "PayNow QR" box and pick paynow-qr.png 4. Click "Save changes" | G17: "PayNow QR added", then "Company details saved"; a QR code now sits in the box beside the bank fields. | H17: Same as 1.0 | I17: Dane
A18: 2 | B18: 2.04 | C18: Your company on paper | D18: Company | E18: Add a second company you issue quotes under | F18: 1. Click "Add an entity" 2. "Entity name": Demo Studio Carpentry Pte Ltd 3. Switch off "GST-registered"; under "Letterhead" fill "UEN / Co. Reg. No." 202512345K 4. Click "Save changes" | G18: "Company details saved". The new company has its own bank, PayNow and letterhead fields, and a bin to remove it, since nothing uses it yet. | H18: Different from 1.0: an entity in use is retired, never deleted | I18: Dane
A19: 2 | B19: 2.05 | C19: Your company on paper | D19: Company | E19: Look at the brand kit every template starts from | F19: 1. At the bottom of Profile, click "Brand kit" 2. Read the page without changing anything | G19: "Templates" opens on its "Brand kit" tab: "Logo and marks", "Colours" and "Fonts", with the default template's first page on the right. | H19: Different from 1.0: one kit every template starts from | I19: Dane
A20: 2 | B20: 2.06 | C20: Your team | D20: Company | E20: See who works in the studio and their roles | F20: 1. Click "Company" in the side navigation 2. Click "Members" | G20: "People and roles": Dane (you) is the Owner; James is a Manager with "Team: Michelle, Sarah"; every row has a role and a lead count. | H20: Same as 1.0 | I20: Dane
A21: 2 | B21: 2.07 | C21: Your team | D21: Company | E21: Add a new designer to the team | F21: 1. Click "Add member" 2. "Name": Kavya Menon · "Role": Designer · "Phone": 9123 4567 · "Email": kavya@demostudio.sg 3. Click "Add member" | G21: "Kavya Menon added as a Designer"; she appears among the designers with "0 leads". | H21: Different from 1.0: 1.0 only emailed a request to OpenMaison | I21: Dane
A22: 2 | B22: 2.08 | C22: Your team | D22: Company | E22: Put Kavya in James's team | F22: 1. In Kavya's row open "Reports to" 2. Pick James | G22: "Kavya Menon now reports to James"; James's row now reads "Team: Kavya Menon, Michelle, Sarah". | H22: Different from 1.0: every studio can have managers | I22: Dane
A23: 2 | B23: 2.09 | C23: Your team | D23: Company | E23: Tell the studio which leads Kavya should get | F23: 1. In Kavya's row click "Preferences" 2. "Specialty": Condo kitchens 3. Beside "Property type" set "Priority" to "Must match", then pick the "Condo 3-bedder" chip 4. Click "Save preferences" | G23: "Lead preferences saved"; her row reads "Condo kitchens · Condo 3-bedder (must)". | H23: Different from 1.0: four categories; Scope is left out | I23: Dane
A24: 2 | B24: 2.10 | C24: Your team | D24: Company | E24: Stop new leads going to Kavya for now | F24: 1. In Kavya's row switch off "Open to new leads" | G24: "Kavya Menon is closed to new leads"; a yellow "Closed to new leads" tag appears on her row. | H24: Same as 1.0 | I24: Dane
A25: 2 | B25: 2.11 | C25: Your team | D25: Company | E25: Try to change your own role | F25: 1. On your own row (Dane), point at the "Role" box | G25: The box is greyed out and a tip says "Nobody changes their own role". | H25: Different from 1.0: the rule is enforced, not just hidden | I25: Dane
A26: 2 | B26: 2.12 | C26: Your team | D26: Company | E26: Deactivate Kavya, then change your mind | F26: 1. In Kavya's row click "Deactivate" 2. Read the box, then click "Deactivate" 3. Click "Undo" in the message at the bottom | G26: The box says she leaves every picker and "Nothing open is on their name." After Undo: "Kavya Menon is back", still in James's team. | H26: Different from 1.0: open work is named first, and Undo | I26: Dane
... A51: 2 | B51: 2.37 | C51: Leave the studio as you found it | D51: Company | E51: Leave Kavya out and remove the test company | F51: 1. Company › "Members": click "Deactivate" on Kavya, then "Deactivate" in the box 2. Company › "Profile": click the bin on Demo Studio Carpentry Pte Ltd 3. Click "Save changes" 4. Open Settings › "Studio" | G51: Studio lists one entity, Demo Studio Pte Ltd; the Team card's "Deactivated" line names Kavya Menon, out of every picker. | H51: Same as 1.0 | I51: Dane
A52: Chapter 3 · Build your library — Price book, templates and the question bank.
A53: 3 | B53: 3.01 | C53: Open the price book | D53: Price book | E53: Open the studio's price book | F53: 1. Click "Company" in the side navigation 2. Click "Price book" | G53: "Price book" opens on "My Items": the "Wet works" and "Kitchen" folders, item cards with unit prices, a "1 proposed" chip and "Kind: All". | H53: Different from 1.0: under Company, not Accounts | I53: Dane
A54: 3 | B54: 3.02 | C54: Open the price book | D54: Price book | E54: See one product from two suppliers | F54: 1. Click the "Wet works" folder 2. Look at the two "Homogeneous tiles 600×600, supply and lay" cards 3. Click "My Items" in the path at the top to go back | G54: The same tile shows twice — "by Hafary" and "by Soon Bee Huat", each S$11.00 / sqft: one item per supplier. | H54: Different from 1.0: one vendor per item, not several | I54: Dane
A55: 3 | B55: 3.03 | C55: Add the fluted panel | D55: Price book | E55: Add a new item with a price in cents | F55: 1. Click "New" › "New item" 2. "Item name": Fluted feature wall panel · "Description": Oak veneer fluted panel, 20 mm slats, supply and install 3. "Kind": Purchase · "Unit": sqft 4. "Cost (S$)": 28.50 · "Markup (S$)": 11.50 | G55: Under Markup it reads "Unit price S$40.00" — the cents are kept exactly as typed. | H55: Different from 1.0: markup in S$, not a percentage | I55: Dane
A56: 3 | B56: 3.04 | C56: Add the fluted panel | D56: Price book | E56: Give it a trade, a supplier and a product link | F56: 1. "Category": pick Carpentry (the list is the studio's trades) 2. "Vendor": Timber Craft 3. "Website link": www.example.com/fluted-panel 4. Click "Add to My Items" | G56: A message says "Fluted feature wall panel added to My Items"; its card reads "by Timber Craft · S$40.00 / sqft · Carpentry". | H56: Same as 1.0 | I56: Dane
A57: 3 | B57: 3.05 | C57: Add the fluted panel | D57: Price book | E57: Add a photo of the panel | F57: 1. Click the "Fluted feature wall panel" card 2. In "Edit item", click the "Photo" box and pick fluted-panel.jpg 3. Click "Save" | G57: A message says "Item saved" and the card now shows your photo instead of the cart icon. | H57: Same as 1.0 | I57: Dane
A58: 3 | B58: 3.06 | C58: Add the fluted panel | D58: Price book | E58: Change its cost and read the item's history | F58: 1. Open the fluted panel again 2. "Cost (S$)": 30.50, then click "Save" 3. Open it once more and scroll down to "History" | G58: History lists "Added by Dane" and two "Changed by Dane" entries — "Photo added" and "Cost S$28.50 → S$30.50". Unit price is now S$42.00. | H58: Different from 1.0: every change kept, before → after | I58: Dane
A59: 3 | B59: 3.07 | C59: Find, sort and change many | D59: Price book | E59: Sort the list by price | F59: 1. Click "List view" (the list icon, top right) 2. Click the "Unit price" column heading 3. Click it again | G59: Items sort cheapest first with an up arrow, then dearest first with a down arrow. | H59: Same as 1.0 | I59: Dane
A60: 3 | B60: 3.08 | C60: Find, sort and change many | D60: Price book | E60: Show only one trade's items | F60: 1. Click "Filters" (the funnel icon) 2. "Category": Tiling, then click "Done" 3. When checked, open "Filters" again and click "Clear All" | G60: Only the two Homogeneous tiles items show, each marked with its folder "Wet works"; "Clear All" brings every item back. | H60: Different from 1.0: a category filter, not grouped lists | I60: Dane
A61: 3 | B61: 3.09 | C61: Find, sort and change many | D61: Price book | E61: Look at an item a designer proposed | F61: 1. Click the "1 proposed" chip at the top 2. Click "Skirting, PVC 80 mm" 3. Read the bar at the top, then click "Cancel" 4. Click "1 proposed" again to see every item | G61: The bar says Sarah proposed it and only their quotes use it until approved; "Send back…" and "Approve" wait for chapter 10. | H61: Different from 1.0: not used studio-wide until approved | I61: Dane
A62: 3 | B62: 3.10 | C62: Find, sort and change many | D62: Price book | E62: Re-price two items at once, then undo | F62: 1. Tick "Vinyl flooring, supply and install" and "Electrical point, new" 2. In the bar at the bottom, click "Set markup" 3. "Markup (% of cost)": 30, then click "Apply to 2 items" 4. On the message "2 items changed", click "Undo" straight away | G62: Unit prices change to S$7.15 and S$71.50, then Undo puts them back to S$7.00 and S$70.00. | H62: Different from 1.0: a markup % re-prices the items | I62: Dane
A63: 3 | B63: 3.11 | C63: Import and export | D63: Price book | E63: Export My Items to a spreadsheet | F63: 1. Click the ⋮ menu ("More options", top right) 2. Click "Export My Items…" 3. Keep "All items" and "Choose file format": CSV 4. Click "Export" | G63: my-items.csv downloads and a message says how many items were exported as CSV; the file has an Item column with every name. | H63: Different from 1.0: live items only, with their names | I63: Dane
A64: 3 | B64: 3.12 | C64: Import and export | D64: Price book | E64: Import a supplier's price list | F64: 1. Click "New" › "Import from a spreadsheet…" 2. Drop supplier-price-list.csv on the box (or click "browse") 3. In "Import into My Items", read the "In My Items" column and the notes below | G64: Rows read New · Updates its price · New · Repeats — skipped; notes name the match, the repeat and new trade "Glass & Mirror". | H64: Different from 1.0: matches existing items; no PDF reading | I64: Dane
...

Sheet UAT · Oliva
A1: Oliva — the whole story, chapter by chapter
A2: Go in order. Read “Try this”, follow “How”, compare with “You should see”, then pick a Result. Write in “What happened” only when it is not ✅. White columns are yours; grey columns are Vicky’s and Dane’s. See “UAT · Start here” first.
A3: Ch | B3: Step | C3: Scene | D3: Module | E3: Try this | F3: How | G3: You should see | H3: In 1.0 | I3: You are | J3: Result | K3: What happened (only if not ✅) | L3: Screenshot link | M3: Date tested | N3: Our reply | O3: Status | P3: Re-tested
A4: Chapter 1 · First login — Look around your new workspace.
A5: 1 | B5: 1.01 | C5: Start fresh and look around | D5: Shell | E5: Start from the studio's day-one data | F5: 1. Open http://localhost:3000 2. Click the ✦ "Maison AI" button, bottom right 3. Click "Reset prototype to base" 4. Click "Reset" | G5: A "Reset the prototype?" box warns that anything tried is lost; after "Reset" the Leads page reloads. | H5: New in 2.0 | I5: Dane
A6: 1 | B6: 1.02 | C6: Start fresh and look around | D6: Shell | E6: Find your way around the side navigation | F6: 1. Point at the logo, top left, and click "Expand navigation" 2. Read the items from top to bottom 3. Click "Collapse navigation" | G6: Search ("/"), Dashboard, Tasks, Projects, Leads, Marketplace, Company, Qanvast Ops; then Upgrade, Tools, Chat, Notifications, Settings; Demo Studio at the bottom. | H6: Different from 1.0: Settings in the side navigation, not the profile menu | I6: Dane
A7: 1 | B7: 1.03 | C7: Your leads at a glance | D7: Leads | E7: See the studio's leads at a glance | F7: 1. Click "Leads" in the side navigation 2. Look at the chip above the table, the rows and the bottom of the screen | G7: The chip reads "All Leads (27)"; unopened new leads (Marcus Chen, Nur Aisyah) have a coloured left edge; a "Review imported leads" bar waits below. | H7: Different from 1.0: unopened new leads are marked | I7: Dane
A8: 1 | B8: 1.04 | C8: Your leads at a glance | D8: Leads | E8: Find a lead fast with the / key | F8: 1. On Leads, press the / key 2. Type Kenji 3. Clear the search box | G8: The search box takes the cursor; only Kenji Sato stays in the list; clearing the box brings everyone back. | H8: Same as 1.0 | I8: Dane
A9: 1 | B9: 1.05 | C9: Your leads at a glance | D9: Leads | E9: Try editing the lead stages | F9: 1. Click the "All Leads (27)" chip 2. Read the stage list 3. Click "Manage Stages" | G9: Each stage is listed with its count under Active and Inactive; "Manage Stages" answers "Coming soon in OpenMaison 2.0". | H9: Different from 1.0: stages are fixed; 1.0 edited its funnel | I9: Dane
A10: 1 | B10: 1.06 | C10: Where everything else lives | D10: Shell | E10: See the tools the studio can use | F10: 1. Click "Tools" in the side navigation 2. Read the tiles 3. Click "AI Visualizer" | G10: Nine tiles, starting with Quotes, Quote X-Ray and Contracts; "AI Visualizer" opens the AI Visualizer — Kevin Ng's design and the "Showroom ideas" folder (REG-673). | H10: Same as 1.0 | I10: Dane
A11: 1 | B11: 1.07 | C11: Where everything else lives | D11: Company | E11: See where the studio's records are kept | F11: 1. Click "Company" in the side navigation 2. Read the two groups 3. Press Esc | G11: "Studio": Profile, Members, Questionnaire, Templates ("1 awaiting"), Price book ("1 proposed"). "Operations": Finance and Reports marked "Soon", Integrations. | H11: Different from 1.0: records under Company, rules under Settings | I11: Dane
A12: 1 | B12: 1.08 | C12: Where everything else lives | D12: Notifications | E12: Check what is waiting for you in the bell | F12: 1. Click "Notifications" (the bell) in the side navigation 2. Read the list 3. Close it without clicking a row | G12: A "Notifications" panel lists notices newest first, e.g. "New lead: Nur Aisyah"; unread ones have a dot; "Notification settings" sits at the foot. | H12: Different from 1.0: follow-ups due appear in the same list | I12: Dane
A13: 1 | B13: 1.09 | C13: Where everything else lives | D13: Shell | E13: Ask Maison AI for help on the Leads page | F13: 1. On Leads, click the ✦ "Maison AI" button 2. Read the suggestions 3. Click "Which leads need follow-up today?" | G13: Suggestions about your leads sit above "Reset prototype to base"; picking one answers "Coming soon in OpenMaison 2.0". | H13: Different from 1.0: scripted suggestions only, in the prototype | I13: Dane
A14: Chapter 2 · Set up your studio — Company details, your team and the studio’s rules.
A15: 2 | B15: 2.01 | C15: Your company on paper | D15: Company | E15: Open your company's profile | F15: 1. Click "Company" in the side navigation 2. Click "Profile" | G15: "Company details" shows Demo Studio Pte Ltd, its UEN and address; the right side shows "Default template · Default Quote PDF". | H15: Different from 1.0: company records live under Company, not Accounts | I15: Dane
A16: 2 | B16: 2.02 | C16: Your company on paper | D16: Company | E16: Add a tagline and your Instagram handle | F16: 1. In "Tagline" type Homes that feel like you 2. Under "Social links", in "Instagram" type @demostudio.sg 3. Click "Save changes" | G16: A message says "Company details saved"; "Save changes" and "Discard" grey out until you change something again. | H16: Same as 1.0 | I16: Dane
A17: 2 | B17: 2.03 | C17: Your company on paper | D17: Company | E17: Put the studio's bank account and PayNow on file | F17: 1. Scroll to "Issuing entities & bank details" 2. For Demo Studio Pte Ltd fill "Bank" DBS Bank, "Account number" 072-123456-7, "SWIFT / BIC" DBSSSGSG, "PayNow (UEN or mobile)" 201234567M 3. Click the "PayNow QR" box and pick paynow-qr.png 4. Click "Save changes" | G17: "PayNow QR added", then "Company details saved"; a QR code now sits in the box beside the bank fields. | H17: Same as 1.0 | I17: Dane
A18: 2 | B18: 2.04 | C18: Your company on paper | D18: Company | E18: Add a second company you issue quotes under | F18: 1. Click "Add an entity" 2. "Entity name": Demo Studio Carpentry Pte Ltd 3. Switch off "GST-registered"; under "Letterhead" fill "UEN / Co. Reg. No." 202512345K 4. Click "Save changes" | G18: "Company details saved". The new company has its own bank, PayNow and letterhead fields, and a bin to remove it, since nothing uses it yet. | H18: Different from 1.0: an entity in use is retired, never deleted | I18: Dane
A19: 2 | B19: 2.05 | C19: Your company on paper | D19: Company | E19: Look at the brand kit every template starts from | F19: 1. At the bottom of Profile, click "Brand kit" 2. Read the page without changing anything | G19: "Templates" opens on its "Brand kit" tab: "Logo and marks", "Colours" and "Fonts", with the default template's first page on the right. | H19: Different from 1.0: one kit every template starts from | I19: Dane
A20: 2 | B20: 2.06 | C20: Your team | D20: Company | E20: See who works in the studio and their roles | F20: 1. Click "Company" in the side navigation 2. Click "Members" | G20: "People and roles": Dane (you) is the Owner; James is a Manager with "Team: Michelle, Sarah"; every row has a role and a lead count. | H20: Same as 1.0 | I20: Dane
A21: 2 | B21: 2.07 | C21: Your team | D21: Company | E21: Add a new designer to the team | F21: 1. Click "Add member" 2. "Name": Kavya Menon · "Role": Designer · "Phone": 9123 4567 · "Email": kavya@demostudio.sg 3. Click "Add member" | G21: "Kavya Menon added as a Designer"; she appears among the designers with "0 leads". | H21: Different from 1.0: 1.0 only emailed a request to OpenMaison | I21: Dane
A22: 2 | B22: 2.08 | C22: Your team | D22: Company | E22: Put Kavya in James's team | F22: 1. In Kavya's row open "Reports to" 2. Pick James | G22: "Kavya Menon now reports to James"; James's row now reads "Team: Kavya Menon, Michelle, Sarah". | H22: Different from 1.0: every studio can have managers | I22: Dane
A23: 2 | B23: 2.09 | C23: Your team | D23: Company | E23: Tell the studio which leads Kavya should get | F23: 1. In Kavya's row click "Preferences" 2. "Specialty": Condo kitchens 3. Beside "Property type" set "Priority" to "Must match", then pick the "Condo 3-bedder" chip 4. Click "Save preferences" | G23: "Lead preferences saved"; her row reads "Condo kitchens · Condo 3-bedder (must)". | H23: Different from 1.0: four categories; Scope is left out | I23: Dane
A24: 2 | B24: 2.10 | C24: Your team | D24: Company | E24: Stop new leads going to Kavya for now | F24: 1. In Kavya's row switch off "Open to new leads" | G24: "Kavya Menon is closed to new leads"; a yellow "Closed to new leads" tag appears on her row. | H24: Same as 1.0 | I24: Dane
A25: 2 | B25: 2.11 | C25: Your team | D25: Company | E25: Try to change your own role | F25: 1. On your own row (Dane), point at the "Role" box | G25: The box is greyed out and a tip says "Nobody changes their own role". | H25: Different from 1.0: the rule is enforced, not just hidden | I25: Dane
A26: 2 | B26: 2.12 | C26: Your team | D26: Company | E26: Deactivate Kavya, then change your mind | F26: 1. In Kavya's row click "Deactivate" 2. Read the box, then click "Deactivate" 3. Click "Undo" in the message at the bottom | G26: The box says she leaves every picker and "Nothing open is on their name." After Undo: "Kavya Menon is back", still in James's team. | H26: Different from 1.0: open work is named first, and Undo | I26: Dane
... A51: 2 | B51: 2.37 | C51: Leave the studio as you found it | D51: Company | E51: Leave Kavya out and remove the test company | F51: 1. Company › "Members": click "Deactivate" on Kavya, then "Deactivate" in the box 2. Company › "Profile": click the bin on Demo Studio Carpentry Pte Ltd 3. Click "Save changes" 4. Open Settings › "Studio" | G51: Studio lists one entity, Demo Studio Pte Ltd; the Team card's "Deactivated" line names Kavya Menon, out of every picker. | H51: Same as 1.0 | I51: Dane
A52: Chapter 3 · Build your library — Price book, templates and the question bank.
A53: 3 | B53: 3.01 | C53: Open the price book | D53: Price book | E53: Open the studio's price book | F53: 1. Click "Company" in the side navigation 2. Click "Price book" | G53: "Price book" opens on "My Items": the "Wet works" and "Kitchen" folders, item cards with unit prices, a "1 proposed" chip and "Kind: All". | H53: Different from 1.0: under Company, not Accounts | I53: Dane
A54: 3 | B54: 3.02 | C54: Open the price book | D54: Price book | E54: See one product from two suppliers | F54: 1. Click the "Wet works" folder 2. Look at the two "Homogeneous tiles 600×600, supply and lay" cards 3. Click "My Items" in the path at the top to go back | G54: The same tile shows twice — "by Hafary" and "by Soon Bee Huat", each S$11.00 / sqft: one item per supplier. | H54: Different from 1.0: one vendor per item, not several | I54: Dane
A55: 3 | B55: 3.03 | C55: Add the fluted panel | D55: Price book | E55: Add a new item with a price in cents | F55: 1. Click "New" › "New item" 2. "Item name": Fluted feature wall panel · "Description": Oak veneer fluted panel, 20 mm slats, supply and install 3. "Kind": Purchase · "Unit": sqft 4. "Cost (S$)": 28.50 · "Markup (S$)": 11.50 | G55: Under Markup it reads "Unit price S$40.00" — the cents are kept exactly as typed. | H55: Different from 1.0: markup in S$, not a percentage | I55: Dane
A56: 3 | B56: 3.04 | C56: Add the fluted panel | D56: Price book | E56: Give it a trade, a supplier and a product link | F56: 1. "Category": pick Carpentry (the list is the studio's trades) 2. "Vendor": Timber Craft 3. "Website link": www.example.com/fluted-panel 4. Click "Add to My Items" | G56: A message says "Fluted feature wall panel added to My Items"; its card reads "by Timber Craft · S$40.00 / sqft · Carpentry". | H56: Same as 1.0 | I56: Dane
A57: 3 | B57: 3.05 | C57: Add the fluted panel | D57: Price book | E57: Add a photo of the panel | F57: 1. Click the "Fluted feature wall panel" card 2. In "Edit item", click the "Photo" box and pick fluted-panel.jpg 3. Click "Save" | G57: A message says "Item saved" and the card now shows your photo instead of the cart icon. | H57: Same as 1.0 | I57: Dane
A58: 3 | B58: 3.06 | C58: Add the fluted panel | D58: Price book | E58: Change its cost and read the item's history | F58: 1. Open the fluted panel again 2. "Cost (S$)": 30.50, then click "Save" 3. Open it once more and scroll down to "History" | G58: History lists "Added by Dane" and two "Changed by Dane" entries — "Photo added" and "Cost S$28.50 → S$30.50". Unit price is now S$42.00. | H58: Different from 1.0: every change kept, before → after | I58: Dane
A59: 3 | B59: 3.07 | C59: Find, sort and change many | D59: Price book | E59: Sort the list by price | F59: 1. Click "List view" (the list icon, top right) 2. Click the "Unit price" column heading 3. Click it again | G59: Items sort cheapest first with an up arrow, then dearest first with a down arrow. | H59: Same as 1.0 | I59: Dane
A60: 3 | B60: 3.08 | C60: Find, sort and change many | D60: Price book | E60: Show only one trade's items | F60: 1. Click "Filters" (the funnel icon) 2. "Category": Tiling, then click "Done" 3. When checked, open "Filters" again and click "Clear All" | G60: Only the two Homogeneous tiles items show, each marked with its folder "Wet works"; "Clear All" brings every item back. | H60: Different from 1.0: a category filter, not grouped lists | I60: Dane
A61: 3 | B61: 3.09 | C61: Find, sort and change many | D61: Price book | E61: Look at an item a designer proposed | F61: 1. Click the "1 proposed" chip at the top 2. Click "Skirting, PVC 80 mm" 3. Read the bar at the top, then click "Cancel" 4. Click "1 proposed" again to see every item | G61: The bar says Sarah proposed it and only their quotes use it until approved; "Send back…" and "Approve" wait for chapter 10. | H61: Different from 1.0: not used studio-wide until approved | I61: Dane
A62: 3 | B62: 3.10 | C62: Find, sort and change many | D62: Price book | E62: Re-price two items at once, then undo | F62: 1. Tick "Vinyl flooring, supply and install" and "Electrical point, new" 2. In the bar at the bottom, click "Set markup" 3. "Markup (% of cost)": 30, then click "Apply to 2 items" 4. On the message "2 items changed", click "Undo" straight away | G62: Unit prices change to S$7.15 and S$71.50, then Undo puts them back to S$7.00 and S$70.00. | H62: Different from 1.0: a markup % re-prices the items | I62: Dane
A63: 3 | B63: 3.11 | C63: Import and export | D63: Price book | E63: Export My Items to a spreadsheet | F63: 1. Click the ⋮ menu ("More options", top right) 2. Click "Export My Items…" 3. Keep "All items" and "Choose file format": CSV 4. Click "Export" | G63: my-items.csv downloads and a message says how many items were exported as CSV; the file has an Item column with every name. | H63: Different from 1.0: live items only, with their names | I63: Dane
A64: 3 | B64: 3.12 | C64: Import and export | D64: Price book | E64: Import a supplier's price list | F64: 1. Click "New" › "Import from a spreadsheet…" 2. Drop supplier-price-list.csv on the box (or click "browse") 3. In "Import into My Items", read the "In My Items" column and the notes below | G64: Rows read New · Updates its price · New · Repeats — skipped; notes name the match, the repeat and new trade "Glass & Mirror". | H64: Different from 1.0: matches existing items; no PDF reading | I64: Dane
...

Sheet UAT · Swati
A1: Swati — the whole story, chapter by chapter
A2: Go in order. Read “Try this”, follow “How”, compare with “You should see”, then pick a Result. Write in “What happened” only when it is not ✅. White columns are yours; grey columns are Vicky’s and Dane’s. See “UAT · Start here” first.
A3: Ch | B3: Step | C3: Scene | D3: Module | E3: Try this | F3: How | G3: You should see | H3: In 1.0 | I3: You are | J3: Result | K3: What happened (only if not ✅) | L3: Screenshot link | M3: Date tested | N3: Our reply | O3: Status | P3: Re-tested
A4: Chapter 1 · First login — Look around your new workspace.
A5: 1 | B5: 1.01 | C5: Start fresh and look around | D5: Shell | E5: Start from the studio's day-one data | F5: 1. Open http://localhost:3000 2. Click the ✦ "Maison AI" button, bottom right 3. Click "Reset prototype to base" 4. Click "Reset" | G5: A "Reset the prototype?" box warns that anything tried is lost; after "Reset" the Leads page reloads. | H5: New in 2.0 | I5: Dane
A6: 1 | B6: 1.02 | C6: Start fresh and look around | D6: Shell | E6: Find your way around the side navigation | F6: 1. Point at the logo, top left, and click "Expand navigation" 2. Read the items from top to bottom 3. Click "Collapse navigation" | G6: Search ("/"), Dashboard, Tasks, Projects, Leads, Marketplace, Company, Qanvast Ops; then Upgrade, Tools, Chat, Notifications, Settings; Demo Studio at the bottom. | H6: Different from 1.0: Settings in the side navigation, not the profile menu | I6: Dane
A7: 1 | B7: 1.03 | C7: Your leads at a glance | D7: Leads | E7: See the studio's leads at a glance | F7: 1. Click "Leads" in the side navigation 2. Look at the chip above the table, the rows and the bottom of the screen | G7: The chip reads "All Leads (27)"; unopened new leads (Marcus Chen, Nur Aisyah) have a coloured left edge; a "Review imported leads" bar waits below. | H7: Different from 1.0: unopened new leads are marked | I7: Dane
A8: 1 | B8: 1.04 | C8: Your leads at a glance | D8: Leads | E8: Find a lead fast with the / key | F8: 1. On Leads, press the / key 2. Type Kenji 3. Clear the search box | G8: The search box takes the cursor; only Kenji Sato stays in the list; clearing the box brings everyone back. | H8: Same as 1.0 | I8: Dane
A9: 1 | B9: 1.05 | C9: Your leads at a glance | D9: Leads | E9: Try editing the lead stages | F9: 1. Click the "All Leads (27)" chip 2. Read the stage list 3. Click "Manage Stages" | G9: Each stage is listed with its count under Active and Inactive; "Manage Stages" answers "Coming soon in OpenMaison 2.0". | H9: Different from 1.0: stages are fixed; 1.0 edited its funnel | I9: Dane
A10: 1 | B10: 1.06 | C10: Where everything else lives | D10: Shell | E10: See the tools the studio can use | F10: 1. Click "Tools" in the side navigation 2. Read the tiles 3. Click "AI Visualizer" | G10: Nine tiles, starting with Quotes, Quote X-Ray and Contracts; "AI Visualizer" opens the AI Visualizer — Kevin Ng's design and the "Showroom ideas" folder (REG-673). | H10: Same as 1.0 | I10: Dane
A11: 1 | B11: 1.07 | C11: Where everything else lives | D11: Company | E11: See where the studio's records are kept | F11: 1. Click "Company" in the side navigation 2. Read the two groups 3. Press Esc | G11: "Studio": Profile, Members, Questionnaire, Templates ("1 awaiting"), Price book ("1 proposed"). "Operations": Finance and Reports marked "Soon", Integrations. | H11: Different from 1.0: records under Company, rules under Settings | I11: Dane
A12: 1 | B12: 1.08 | C12: Where everything else lives | D12: Notifications | E12: Check what is waiting for you in the bell | F12: 1. Click "Notifications" (the bell) in the side navigation 2. Read the list 3. Close it without clicking a row | G12: A "Notifications" panel lists notices newest first, e.g. "New lead: Nur Aisyah"; unread ones have a dot; "Notification settings" sits at the foot. | H12: Different from 1.0: follow-ups due appear in the same list | I12: Dane
A13: 1 | B13: 1.09 | C13: Where everything else lives | D13: Shell | E13: Ask Maison AI for help on the Leads page | F13: 1. On Leads, click the ✦ "Maison AI" button 2. Read the suggestions 3. Click "Which leads need follow-up today?" | G13: Suggestions about your leads sit above "Reset prototype to base"; picking one answers "Coming soon in OpenMaison 2.0". | H13: Different from 1.0: scripted suggestions only, in the prototype | I13: Dane
A14: Chapter 2 · Set up your studio — Company details, your team and the studio’s rules.
A15: 2 | B15: 2.01 | C15: Your company on paper | D15: Company | E15: Open your company's profile | F15: 1. Click "Company" in the side navigation 2. Click "Profile" | G15: "Company details" shows Demo Studio Pte Ltd, its UEN and address; the right side shows "Default template · Default Quote PDF". | H15: Different from 1.0: company records live under Company, not Accounts | I15: Dane
A16: 2 | B16: 2.02 | C16: Your company on paper | D16: Company | E16: Add a tagline and your Instagram handle | F16: 1. In "Tagline" type Homes that feel like you 2. Under "Social links", in "Instagram" type @demostudio.sg 3. Click "Save changes" | G16: A message says "Company details saved"; "Save changes" and "Discard" grey out until you change something again. | H16: Same as 1.0 | I16: Dane
A17: 2 | B17: 2.03 | C17: Your company on paper | D17: Company | E17: Put the studio's bank account and PayNow on file | F17: 1. Scroll to "Issuing entities & bank details" 2. For Demo Studio Pte Ltd fill "Bank" DBS Bank, "Account number" 072-123456-7, "SWIFT / BIC" DBSSSGSG, "PayNow (UEN or mobile)" 201234567M 3. Click the "PayNow QR" box and pick paynow-qr.png 4. Click "Save changes" | G17: "PayNow QR added", then "Company details saved"; a QR code now sits in the box beside the bank fields. | H17: Same as 1.0 | I17: Dane
A18: 2 | B18: 2.04 | C18: Your company on paper | D18: Company | E18: Add a second company you issue quotes under | F18: 1. Click "Add an entity" 2. "Entity name": Demo Studio Carpentry Pte Ltd 3. Switch off "GST-registered"; under "Letterhead" fill "UEN / Co. Reg. No." 202512345K 4. Click "Save changes" | G18: "Company details saved". The new company has its own bank, PayNow and letterhead fields, and a bin to remove it, since nothing uses it yet. | H18: Different from 1.0: an entity in use is retired, never deleted | I18: Dane
A19: 2 | B19: 2.05 | C19: Your company on paper | D19: Company | E19: Look at the brand kit every template starts from | F19: 1. At the bottom of Profile, click "Brand kit" 2. Read the page without changing anything | G19: "Templates" opens on its "Brand kit" tab: "Logo and marks", "Colours" and "Fonts", with the default template's first page on the right. | H19: Different from 1.0: one kit every template starts from | I19: Dane
A20: 2 | B20: 2.06 | C20: Your team | D20: Company | E20: See who works in the studio and their roles | F20: 1. Click "Company" in the side navigation 2. Click "Members" | G20: "People and roles": Dane (you) is the Owner; James is a Manager with "Team: Michelle, Sarah"; every row has a role and a lead count. | H20: Same as 1.0 | I20: Dane
A21: 2 | B21: 2.07 | C21: Your team | D21: Company | E21: Add a new designer to the team | F21: 1. Click "Add member" 2. "Name": Kavya Menon · "Role": Designer · "Phone": 9123 4567 · "Email": kavya@demostudio.sg 3. Click "Add member" | G21: "Kavya Menon added as a Designer"; she appears among the designers with "0 leads". | H21: Different from 1.0: 1.0 only emailed a request to OpenMaison | I21: Dane
A22: 2 | B22: 2.08 | C22: Your team | D22: Company | E22: Put Kavya in James's team | F22: 1. In Kavya's row open "Reports to" 2. Pick James | G22: "Kavya Menon now reports to James"; James's row now reads "Team: Kavya Menon, Michelle, Sarah". | H22: Different from 1.0: every studio can have managers | I22: Dane
A23: 2 | B23: 2.09 | C23: Your team | D23: Company | E23: Tell the studio which leads Kavya should get | F23: 1. In Kavya's row click "Preferences" 2. "Specialty": Condo kitchens 3. Beside "Property type" set "Priority" to "Must match", then pick the "Condo 3-bedder" chip 4. Click "Save preferences" | G23: "Lead preferences saved"; her row reads "Condo kitchens · Condo 3-bedder (must)". | H23: Different from 1.0: four categories; Scope is left out | I23: Dane
A24: 2 | B24: 2.10 | C24: Your team | D24: Company | E24: Stop new leads going to Kavya for now | F24: 1. In Kavya's row switch off "Open to new leads" | G24: "Kavya Menon is closed to new leads"; a yellow "Closed to new leads" tag appears on her row. | H24: Same as 1.0 | I24: Dane
A25: 2 | B25: 2.11 | C25: Your team | D25: Company | E25: Try to change your own role | F25: 1. On your own row (Dane), point at the "Role" box | G25: The box is greyed out and a tip says "Nobody changes their own role". | H25: Different from 1.0: the rule is enforced, not just hidden | I25: Dane
A26: 2 | B26: 2.12 | C26: Your team | D26: Company | E26: Deactivate Kavya, then change your mind | F26: 1. In Kavya's row click "Deactivate" 2. Read the box, then click "Deactivate" 3. Click "Undo" in the message at the bottom | G26: The box says she leaves every picker and "Nothing open is on their name." After Undo: "Kavya Menon is back", still in James's team. | H26: Different from 1.0: open work is named first, and Undo | I26: Dane
... A51: 2 | B51: 2.37 | C51: Leave the studio as you found it | D51: Company | E51: Leave Kavya out and remove the test company | F51: 1. Company › "Members": click "Deactivate" on Kavya, then "Deactivate" in the box 2. Company › "Profile": click the bin on Demo Studio Carpentry Pte Ltd 3. Click "Save changes" 4. Open Settings › "Studio" | G51: Studio lists one entity, Demo Studio Pte Ltd; the Team card's "Deactivated" line names Kavya Menon, out of every picker. | H51: Same as 1.0 | I51: Dane
A52: Chapter 3 · Build your library — Price book, templates and the question bank.
A53: 3 | B53: 3.01 | C53: Open the price book | D53: Price book | E53: Open the studio's price book | F53: 1. Click "Company" in the side navigation 2. Click "Price book" | G53: "Price book" opens on "My Items": the "Wet works" and "Kitchen" folders, item cards with unit prices, a "1 proposed" chip and "Kind: All". | H53: Different from 1.0: under Company, not Accounts | I53: Dane
A54: 3 | B54: 3.02 | C54: Open the price book | D54: Price book | E54: See one product from two suppliers | F54: 1. Click the "Wet works" folder 2. Look at the two "Homogeneous tiles 600×600, supply and lay" cards 3. Click "My Items" in the path at the top to go back | G54: The same tile shows twice — "by Hafary" and "by Soon Bee Huat", each S$11.00 / sqft: one item per supplier. | H54: Different from 1.0: one vendor per item, not several | I54: Dane
A55: 3 | B55: 3.03 | C55: Add the fluted panel | D55: Price book | E55: Add a new item with a price in cents | F55: 1. Click "New" › "New item" 2. "Item name": Fluted feature wall panel · "Description": Oak veneer fluted panel, 20 mm slats, supply and install 3. "Kind": Purchase · "Unit": sqft 4. "Cost (S$)": 28.50 · "Markup (S$)": 11.50 | G55: Under Markup it reads "Unit price S$40.00" — the cents are kept exactly as typed. | H55: Different from 1.0: markup in S$, not a percentage | I55: Dane
A56: 3 | B56: 3.04 | C56: Add the fluted panel | D56: Price book | E56: Give it a trade, a supplier and a product link | F56: 1. "Category": pick Carpentry (the list is the studio's trades) 2. "Vendor": Timber Craft 3. "Website link": www.example.com/fluted-panel 4. Click "Add to My Items" | G56: A message says "Fluted feature wall panel added to My Items"; its card reads "by Timber Craft · S$40.00 / sqft · Carpentry". | H56: Same as 1.0 | I56: Dane
A57: 3 | B57: 3.05 | C57: Add the fluted panel | D57: Price book | E57: Add a photo of the panel | F57: 1. Click the "Fluted feature wall panel" card 2. In "Edit item", click the "Photo" box and pick fluted-panel.jpg 3. Click "Save" | G57: A message says "Item saved" and the card now shows your photo instead of the cart icon. | H57: Same as 1.0 | I57: Dane
A58: 3 | B58: 3.06 | C58: Add the fluted panel | D58: Price book | E58: Change its cost and read the item's history | F58: 1. Open the fluted panel again 2. "Cost (S$)": 30.50, then click "Save" 3. Open it once more and scroll down to "History" | G58: History lists "Added by Dane" and two "Changed by Dane" entries — "Photo added" and "Cost S$28.50 → S$30.50". Unit price is now S$42.00. | H58: Different from 1.0: every change kept, before → after | I58: Dane
A59: 3 | B59: 3.07 | C59: Find, sort and change many | D59: Price book | E59: Sort the list by price | F59: 1. Click "List view" (the list icon, top right) 2. Click the "Unit price" column heading 3. Click it again | G59: Items sort cheapest first with an up arrow, then dearest first with a down arrow. | H59: Same as 1.0 | I59: Dane
A60: 3 | B60: 3.08 | C60: Find, sort and change many | D60: Price book | E60: Show only one trade's items | F60: 1. Click "Filters" (the funnel icon) 2. "Category": Tiling, then click "Done" 3. When checked, open "Filters" again and click "Clear All" | G60: Only the two Homogeneous tiles items show, each marked with its folder "Wet works"; "Clear All" brings every item back. | H60: Different from 1.0: a category filter, not grouped lists | I60: Dane
A61: 3 | B61: 3.09 | C61: Find, sort and change many | D61: Price book | E61: Look at an item a designer proposed | F61: 1. Click the "1 proposed" chip at the top 2. Click "Skirting, PVC 80 mm" 3. Read the bar at the top, then click "Cancel" 4. Click "1 proposed" again to see every item | G61: The bar says Sarah proposed it and only their quotes use it until approved; "Send back…" and "Approve" wait for chapter 10. | H61: Different from 1.0: not used studio-wide until approved | I61: Dane
A62: 3 | B62: 3.10 | C62: Find, sort and change many | D62: Price book | E62: Re-price two items at once, then undo | F62: 1. Tick "Vinyl flooring, supply and install" and "Electrical point, new" 2. In the bar at the bottom, click "Set markup" 3. "Markup (% of cost)": 30, then click "Apply to 2 items" 4. On the message "2 items changed", click "Undo" straight away | G62: Unit prices change to S$7.15 and S$71.50, then Undo puts them back to S$7.00 and S$70.00. | H62: Different from 1.0: a markup % re-prices the items | I62: Dane
A63: 3 | B63: 3.11 | C63: Import and export | D63: Price book | E63: Export My Items to a spreadsheet | F63: 1. Click the ⋮ menu ("More options", top right) 2. Click "Export My Items…" 3. Keep "All items" and "Choose file format": CSV 4. Click "Export" | G63: my-items.csv downloads and a message says how many items were exported as CSV; the file has an Item column with every name. | H63: Different from 1.0: live items only, with their names | I63: Dane
A64: 3 | B64: 3.12 | C64: Import and export | D64: Price book | E64: Import a supplier's price list | F64: 1. Click "New" › "Import from a spreadsheet…" 2. Drop supplier-price-list.csv on the box (or click "browse") 3. In "Import into My Items", read the "In My Items" column and the notes below | G64: Rows read New · Updates its price · New · Repeats — skipped; notes name the match, the repeat and new trade "Glass & Mirror". | H64: Different from 1.0: matches existing items; no PDF reading | I64: Dane
...

Sheet UAT · Missing or other
A1: Anything the story did not cover
A2: Something you used in 1.0 and cannot find in 2.0, something confusing, a bug outside the steps, or an idea. One row each. White columns are yours; grey columns are Vicky’s and Dane’s.
A3: Date | B3: Who | C3: Type | D3: Module | E3: Where (which screen) | F3: What happened / what you expected | G3: Screenshot link | H3: Our reply | I3: Status | J3: Re-tested

Sheet UAT · Summary
A1: Where we are
A2: Counts fill in by themselves from each tester’s tab. “Open” = ❌ or 🔍 not yet marked Fixed or Won’t change.
A4: By chapter
C5: Dane | I5: Oliva | O5: Swati
A6: Chapter | B6: Steps | C6: Done | D6: ✅ | E6: 🟡 | F6: ❌ | G6: 🔍 | H6: Open | I6: Done | J6: ✅ | K6: 🟡 | L6: ❌ | M6: 🔍 | N6: Open | O6: Done | P6: ✅ | Q6: 🟡 | R6: ❌ | S6: 🔍 | T6: Open
A7: 1 · First login | B7: =COUNTIF('UAT · Dane'!$A:$A,1) | C7: =COUNTIFS('UAT · Dane'!$A:$A,1,'UAT · Dane'!$J:$J,"<>") | D7: =COUNTIFS('UAT · Dane'!$A:$A,1,'UAT · Dane'!$J:$J,"✅ Works") | E7: =COUNTIFS('UAT · Dane'!$A:$A,1,'UAT · Dane'!$J:$J,"🟡 Works, but…") | F7: =COUNTIFS('UAT · Dane'!$A:$A,1,'UAT · Dane'!$J:$J,"❌ Doesn’t work") | G7: =COUNTIFS('UAT · Dane'!$A:$A,1,'UAT · Dane'!$J:$J,"🔍 Couldn’t find it") | H7: =COUNTIFS('UAT · Dane'!$A:$A,1,'UAT · Dane'!$J:$J,"❌ Doesn’t work",'UAT · Dane'!$O:$O,"<>Fixed – please re-test",'UAT · Dane'!$O:$O,"<>Won’t change")+COUNTIFS('UAT · Dane'!$A:$A,1,'UAT · Dane'!$J:$J,"🔍 Couldn’t find it",'UAT · Dane'!$O:$O,"<>Fixed – please re-test",'UAT · Dane'!$O:$O,"<>Won’t change") | I7: =COUNTIFS('UAT · Oliva'!$A:$A,1,'UAT · Oliva'!$J:$J,"<>") | J7: =COUNTIFS('UAT · Oliva'!$A:$A,1,'UAT · Oliva'!$J:$J,"✅ Works") | K7: =COUNTIFS('UAT · Oliva'!$A:$A,1,'UAT · Oliva'!$J:$J,"🟡 Works, but…") | L7: =COUNTIFS('UAT · Oliva'!$A:$A,1,'UAT · Oliva'!$J:$J,"❌ Doesn’t work") | M7: =COUNTIFS('UAT · Oliva'!$A:$A,1,'UAT · Oliva'!$J:$J,"🔍 Couldn’t find it") | N7: =COUNTIFS('UAT · Oliva'!$A:$A,1,'UAT · Oliva'!$J:$J,"❌ Doesn’t work",'UAT · Oliva'!$O:$O,"<>Fixed – please re-test",'UAT · Oliva'!$O:$O,"<>Won’t change")+COUNTIFS('UAT · Oliva'!$A:$A,1,'UAT · Oliva'!$J:$J,"🔍 Couldn’t find it",'UAT · Oliva'!$O:$O,"<>Fixed – please re-test",'UAT · Oliva'!$O:$O,"<>Won’t change") | O7: =COUNTIFS('UAT · Swati'!$A:$A,1,'UAT · Swati'!$J:$J,"<>") | P7: =COUNTIFS('UAT · Swati'!$A:$A,1,'UAT · Swati'!$J:$J,"✅ Works") | Q7: =COUNTIFS('UAT · Swati'!$A:$A,1,'UAT · Swati'!$J:$J,"🟡 Works, but…") | R7: =COUNTIFS('UAT · Swati'!$A:$A,1,'UAT · Swati'!$J:$J,"❌ Doesn’t work") | S7: =COUNTIFS('UAT · Swati'!$A:$A,1,'UAT · Swati'!$J:$J,"🔍 Couldn’t find it") | T7: =COUNTIFS('UAT · Swati'!$A:$A,1,'UAT · Swati'!$J:$J,"❌ Doesn’t work",'UAT · Swati'!$O:$O,"<>Fixed – please re-test",'UAT · Swati'!$O:$O,"<>Won’t change")+COUNTIFS('UAT · Swati'!$A:$A,1,'UAT · Swati'!$J:$J,"🔍 Couldn’t find it",'UAT · Swati'!$O:$O,"<>Fixed – please re-test",'UAT · Swati'!$O:$O,"<>Won’t change")
A8: 2 · Set up your studio | B8: =COUNTIF('UAT · Dane'!$A:$A,2) | C8: =COUNTIFS('UAT · Dane'!$A:$A,2,'UAT · Dane'!$J:$J,"<>") | D8: =COUNTIFS('UAT · Dane'!$A:$A,2,'UAT · Dane'!$J:$J,"✅ Works") | E8: =COUNTIFS('UAT · Dane'!$A:$A,2,'UAT · Dane'!$J:$J,"🟡 Works, but…") | F8: =COUNTIFS('UAT · Dane'!$A:$A,2,'UAT · Dane'!$J:$J,"❌ Doesn’t work") | G8: =COUNTIFS('UAT · Dane'!$A:$A,2,'UAT · Dane'!$J:$J,"🔍 Couldn’t find it") | H8: =COUNTIFS('UAT · Dane'!$A:$A,2,'UAT · Dane'!$J:$J,"❌ Doesn’t work",'UAT · Dane'!$O:$O,"<>Fixed – please re-test",'UAT · Dane'!$O:$O,"<>Won’t change")+COUNTIFS('UAT · Dane'!$A:$A,2,'UAT · Dane'!$J:$J,"🔍 Couldn’t find it",'UAT · Dane'!$O:$O,"<>Fixed – please re-test",'UAT · Dane'!$O:$O,"<>Won’t change") | I8: =COUNTIFS('UAT · Oliva'!$A:$A,2,'UAT · Oliva'!$J:$J,"<>") | J8: =COUNTIFS('UAT · Oliva'!$A:$A,2,'UAT · Oliva'!$J:$J,"✅ Works") | K8: =COUNTIFS('UAT · Oliva'!$A:$A,2,'UAT · Oliva'!$J:$J,"🟡 Works, but…") | L8: =COUNTIFS('UAT · Oliva'!$A:$A,2,'UAT · Oliva'!$J:$J,"❌ Doesn’t work") | M8: =COUNTIFS('UAT · Oliva'!$A:$A,2,'UAT · Oliva'!$J:$J,"🔍 Couldn’t find it") | N8: =COUNTIFS('UAT · Oliva'!$A:$A,2,'UAT · Oliva'!$J:$J,"❌ Doesn’t work",'UAT · Oliva'!$O:$O,"<>Fixed – please re-test",'UAT · Oliva'!$O:$O,"<>Won’t change")+COUNTIFS('UAT · Oliva'!$A:$A,2,'UAT · Oliva'!$J:$J,"🔍 Couldn’t find it",'UAT · Oliva'!$O:$O,"<>Fixed – please re-test",'UAT · Oliva'!$O:$O,"<>Won’t change") | O8: =COUNTIFS('UAT · Swati'!$A:$A,2,'UAT · Swati'!$J:$J,"<>") | P8: =COUNTIFS('UAT · Swati'!$A:$A,2,'UAT · Swati'!$J:$J,"✅ Works") | Q8: =COUNTIFS('UAT · Swati'!$A:$A,2,'UAT · Swati'!$J:$J,"🟡 Works, but…") | R8: =COUNTIFS('UAT · Swati'!$A:$A,2,'UAT · Swati'!$J:$J,"❌ Doesn’t work") | S8: =COUNTIFS('UAT · Swati'!$A:$A,2,'UAT · Swati'!$J:$J,"🔍 Couldn’t find it") | T8: =COUNTIFS('UAT · Swati'!$A:$A,2,'UAT · Swati'!$J:$J,"❌ Doesn’t work",'UAT · Swati'!$O:$O,"<>Fixed – please re-test",'UAT · Swati'!$O:$O,"<>Won’t change")+COUNTIFS('UAT · Swati'!$A:$A,2,'UAT · Swati'!$J:$J,"🔍 Couldn’t find it",'UAT · Swati'!$O:$O,"<>Fixed – please re-test",'UAT · Swati'!$O:$O,"<>Won’t change")
A9: 3 · Build your library | B9: =COUNTIF('UAT · Dane'!$A:$A,3) | C9: =COUNTIFS('UAT · Dane'!$A:$A,3,'UAT · Dane'!$J:$J,"<>") | D9: =COUNTIFS('UAT · Dane'!$A:$A,3,'UAT · Dane'!$J:$J,"✅ Works") | E9: =COUNTIFS('UAT · Dane'!$A:$A,3,'UAT · Dane'!$J:$J,"🟡 Works, but…") | F9: =COUNTIFS('UAT · Dane'!$A:$A,3,'UAT · Dane'!$J:$J,"❌ Doesn’t work") | G9: =COUNTIFS('UAT · Dane'!$A:$A,3,'UAT · Dane'!$J:$J,"🔍 Couldn’t find it") | H9: =COUNTIFS('UAT · Dane'!$A:$A,3,'UAT · Dane'!$J:$J,"❌ Doesn’t work",'UAT · Dane'!$O:$O,"<>Fixed – please re-test",'UAT · Dane'!$O:$O,"<>Won’t change")+COUNTIFS('UAT · Dane'!$A:$A,3,'UAT · Dane'!$J:$J,"🔍 Couldn’t find it",'UAT · Dane'!$O:$O,"<>Fixed – please re-test",'UAT · Dane'!$O:$O,"<>Won’t change") | I9: =COUNTIFS('UAT · Oliva'!$A:$A,3,'UAT · Oliva'!$J:$J,"<>") | J9: =COUNTIFS('UAT · Oliva'!$A:$A,3,'UAT · Oliva'!$J:$J,"✅ Works") | K9: =COUNTIFS('UAT · Oliva'!$A:$A,3,'UAT · Oliva'!$J:$J,"🟡 Works, but…") | L9: =COUNTIFS('UAT · Oliva'!$A:$A,3,'UAT · Oliva'!$J:$J,"❌ Doesn’t work") | M9: =COUNTIFS('UAT · Oliva'!$A:$A,3,'UAT · Oliva'!$J:$J,"🔍 Couldn’t find it") | N9: =COUNTIFS('UAT · Oliva'!$A:$A,3,'UAT · Oliva'!$J:$J,"❌ Doesn’t work",'UAT · Oliva'!$O:$O,"<>Fixed – please re-test",'UAT · Oliva'!$O:$O,"<>Won’t change")+COUNTIFS('UAT · Oliva'!$A:$A,3,'UAT · Oliva'!$J:$J,"🔍 Couldn’t find it",'UAT · Oliva'!$O:$O,"<>Fixed – please re-test",'UAT · Oliva'!$O:$O,"<>Won’t change") | O9: =COUNTIFS('UAT · Swati'!$A:$A,3,'UAT · Swati'!$J:$J,"<>") | P9: =COUNTIFS('UAT · Swati'!$A:$A,3,'UAT · Swati'!$J:$J,"✅ Works") | Q9: =COUNTIFS('UAT · Swati'!$A:$A,3,'UAT · Swati'!$J:$J,"🟡 Works, but…") | R9: =COUNTIFS('UAT · Swati'!$A:$A,3,'UAT · Swati'!$J:$J,"❌ Doesn’t work") | S9: =COUNTIFS('UAT · Swati'!$A:$A,3,'UAT · Swati'!$J:$J,"🔍 Couldn’t find it") | T9: =COUNTIFS('UAT · Swati'!$A:$A,3,'UAT · Swati'!$J:$J,"❌ Doesn’t work",'UAT · Swati'!$O:$O,"<>Fixed – please re-test",'UAT · Swati'!$O:$O,"<>Won’t change")+COUNTIFS('UAT · Swati'!$A:$A,3,'UAT · Swati'!$J:$J,"🔍 Couldn’t find it",'UAT · Swati'!$O:$O,"<>Fixed – please re-test",'UAT · Swati'!$O:$O,"<>Won’t change")
